2022-02-09 11:18:56,736 ERROR: Exception on /user/Sema [GET] [in /home/sema/venv/lib/python3.9/site-packages/flask/app.py:1454]
Traceback (most recent call last):
  File "/home/sema/venv/lib/python3.9/site-packages/flask/app.py", line 2070, in wsgi_app
    response = self.full_dispatch_request()
  File "/home/sema/venv/lib/python3.9/site-packages/flask/app.py", line 1515, in full_dispatch_request
    rv = self.handle_user_exception(e)
  File "/home/sema/venv/lib/python3.9/site-packages/flask/app.py", line 1513, in full_dispatch_request
    rv = self.dispatch_request()
  File "/home/sema/venv/lib/python3.9/site-packages/flask/app.py", line 1499, in dispatch_request
    return self.ensure_sync(self.view_functions[rule.endpoint])(**req.view_args)
  File "/home/sema/venv/lib/python3.9/site-packages/flask_login/utils.py", line 272, in decorated_view
    return func(*args, **kwargs)
  File "/home/sema/microblog/app/main/routes.py", line 76, in user
    return render_template('user.html', user=user, posts=posts.items,
  File "/home/sema/venv/lib/python3.9/site-packages/flask/templating.py", line 147, in render_template
    return _render(
  File "/home/sema/venv/lib/python3.9/site-packages/flask/templating.py", line 128, in _render
    rv = template.render(context)
  File "/home/sema/venv/lib/python3.9/site-packages/jinja2/environment.py", line 1304, in render
    self.environment.handle_exception()
  File "/home/sema/venv/lib/python3.9/site-packages/jinja2/environment.py", line 925, in handle_exception
    raise rewrite_traceback_stack(source=source)
  File "/home/sema/microblog/app/templates/user.html", line 1, in top-level template code
    {% extends "base.html" %}
  File "/home/sema/microblog/app/templates/base.html", line 1, in top-level template code
    {% extends 'bootstrap/base.html' %}
  File "/home/sema/venv/lib/python3.9/site-packages/flask_bootstrap/templates/bootstrap/base.html", line 1, in top-level template code
    {% block doc -%}
  File "/home/sema/venv/lib/python3.9/site-packages/flask_bootstrap/templates/bootstrap/base.html", line 4, in block 'doc'
    {%- block html %}
  File "/home/sema/venv/lib/python3.9/site-packages/flask_bootstrap/templates/bootstrap/base.html", line 20, in block 'html'
    {% block body -%}
  File "/home/sema/venv/lib/python3.9/site-packages/flask_bootstrap/templates/bootstrap/base.html", line 23, in block 'body'
    {% block content -%}
  File "/home/sema/microblog/app/templates/base.html", line 66, in block 'content'
    {% block app_content %}{% endblock %}
  File "/home/sema/microblog/app/templates/user.html", line 33, in block 'app_content'
    <a href="{{ url_for('main.send_message',recipent=user.username) }}">
  File "/home/sema/venv/lib/python3.9/site-packages/flask/helpers.py", line 338, in url_for
    return appctx.app.handle_url_build_error(error, endpoint, values)
  File "/home/sema/venv/lib/python3.9/site-packages/flask/helpers.py", line 325, in url_for
    rv = url_adapter.build(
  File "/home/sema/venv/lib/python3.9/site-packages/werkzeug/routing.py", line 2305, in build
    raise BuildError(endpoint, values, method, self)
werkzeug.routing.BuildError: Could not build url for endpoint 'main.send_message' with values ['recipent']. Did you forget to specify values ['recipient']?
2022-02-09 11:19:06,965 ERROR: Exception on /notifications [GET] [in /home/sema/venv/lib/python3.9/site-packages/flask/app.py:1454]
Traceback (most recent call last):
  File "/home/sema/venv/lib/python3.9/site-packages/flask/app.py", line 2070, in wsgi_app
    response = self.full_dispatch_request()
  File "/home/sema/venv/lib/python3.9/site-packages/flask/app.py", line 1515, in full_dispatch_request
    rv = self.handle_user_exception(e)
  File "/home/sema/venv/lib/python3.9/site-packages/flask/app.py", line 1513, in full_dispatch_request
    rv = self.dispatch_request()
  File "/home/sema/venv/lib/python3.9/site-packages/flask/app.py", line 1499, in dispatch_request
    return self.ensure_sync(self.view_functions[rule.endpoint])(**req.view_args)
  File "/home/sema/venv/lib/python3.9/site-packages/flask_login/utils.py", line 272, in decorated_view
    return func(*args, **kwargs)
  File "/home/sema/microblog/app/main/routes.py", line 202, in notifications
    return jsonify([{
NameError: name 'jsonify' is not defined
2022-02-09 11:19:11,547 ERROR: Exception on /notifications [GET] [in /home/sema/venv/lib/python3.9/site-packages/flask/app.py:1454]
Traceback (most recent call last):
  File "/home/sema/venv/lib/python3.9/site-packages/flask/app.py", line 2070, in wsgi_app
    response = self.full_dispatch_request()
  File "/home/sema/venv/lib/python3.9/site-packages/flask/app.py", line 1515, in full_dispatch_request
    rv = self.handle_user_exception(e)
  File "/home/sema/venv/lib/python3.9/site-packages/flask/app.py", line 1513, in full_dispatch_request
    rv = self.dispatch_request()
  File "/home/sema/venv/lib/python3.9/site-packages/flask/app.py", line 1499, in dispatch_request
    return self.ensure_sync(self.view_functions[rule.endpoint])(**req.view_args)
  File "/home/sema/venv/lib/python3.9/site-packages/flask_login/utils.py", line 272, in decorated_view
    return func(*args, **kwargs)
  File "/home/sema/microblog/app/main/routes.py", line 202, in notifications
    return jsonify([{
NameError: name 'jsonify' is not defined
2022-02-09 11:19:16,972 ERROR: Exception on /notifications [GET] [in /home/sema/venv/lib/python3.9/site-packages/flask/app.py:1454]
Traceback (most recent call last):
  File "/home/sema/venv/lib/python3.9/site-packages/flask/app.py", line 2070, in wsgi_app
    response = self.full_dispatch_request()
  File "/home/sema/venv/lib/python3.9/site-packages/flask/app.py", line 1515, in full_dispatch_request
    rv = self.handle_user_exception(e)
  File "/home/sema/venv/lib/python3.9/site-packages/flask/app.py", line 1513, in full_dispatch_request
    rv = self.dispatch_request()
  File "/home/sema/venv/lib/python3.9/site-packages/flask/app.py", line 1499, in dispatch_request
    return self.ensure_sync(self.view_functions[rule.endpoint])(**req.view_args)
  File "/home/sema/venv/lib/python3.9/site-packages/flask_login/utils.py", line 272, in decorated_view
    return func(*args, **kwargs)
  File "/home/sema/microblog/app/main/routes.py", line 202, in notifications
    return jsonify([{
NameError: name 'jsonify' is not defined
2022-02-09 11:19:21,557 ERROR: Exception on /notifications [GET] [in /home/sema/venv/lib/python3.9/site-packages/flask/app.py:1454]
Traceback (most recent call last):
  File "/home/sema/venv/lib/python3.9/site-packages/flask/app.py", line 2070, in wsgi_app
    response = self.full_dispatch_request()
  File "/home/sema/venv/lib/python3.9/site-packages/flask/app.py", line 1515, in full_dispatch_request
    rv = self.handle_user_exception(e)
  File "/home/sema/venv/lib/python3.9/site-packages/flask/app.py", line 1513, in full_dispatch_request
    rv = self.dispatch_request()
  File "/home/sema/venv/lib/python3.9/site-packages/flask/app.py", line 1499, in dispatch_request
    return self.ensure_sync(self.view_functions[rule.endpoint])(**req.view_args)
  File "/home/sema/venv/lib/python3.9/site-packages/flask_login/utils.py", line 272, in decorated_view
    return func(*args, **kwargs)
  File "/home/sema/microblog/app/main/routes.py", line 202, in notifications
    return jsonify([{
NameError: name 'jsonify' is not defined
2022-02-09 11:19:26,976 ERROR: Exception on /notifications [GET] [in /home/sema/venv/lib/python3.9/site-packages/flask/app.py:1454]
Traceback (most recent call last):
  File "/home/sema/venv/lib/python3.9/site-packages/flask/app.py", line 2070, in wsgi_app
    response = self.full_dispatch_request()
  File "/home/sema/venv/lib/python3.9/site-packages/flask/app.py", line 1515, in full_dispatch_request
    rv = self.handle_user_exception(e)
  File "/home/sema/venv/lib/python3.9/site-packages/flask/app.py", line 1513, in full_dispatch_request
    rv = self.dispatch_request()
  File "/home/sema/venv/lib/python3.9/site-packages/flask/app.py", line 1499, in dispatch_request
    return self.ensure_sync(self.view_functions[rule.endpoint])(**req.view_args)
  File "/home/sema/venv/lib/python3.9/site-packages/flask_login/utils.py", line 272, in decorated_view
    return func(*args, **kwargs)
  File "/home/sema/microblog/app/main/routes.py", line 202, in notifications
    return jsonify([{
NameError: name 'jsonify' is not defined
2022-02-09 11:19:31,557 ERROR: Exception on /notifications [GET] [in /home/sema/venv/lib/python3.9/site-packages/flask/app.py:1454]
Traceback (most recent call last):
  File "/home/sema/venv/lib/python3.9/site-packages/flask/app.py", line 2070, in wsgi_app
    response = self.full_dispatch_request()
  File "/home/sema/venv/lib/python3.9/site-packages/flask/app.py", line 1515, in full_dispatch_request
    rv = self.handle_user_exception(e)
  File "/home/sema/venv/lib/python3.9/site-packages/flask/app.py", line 1513, in full_dispatch_request
    rv = self.dispatch_request()
  File "/home/sema/venv/lib/python3.9/site-packages/flask/app.py", line 1499, in dispatch_request
    return self.ensure_sync(self.view_functions[rule.endpoint])(**req.view_args)
  File "/home/sema/venv/lib/python3.9/site-packages/flask_login/utils.py", line 272, in decorated_view
    return func(*args, **kwargs)
  File "/home/sema/microblog/app/main/routes.py", line 202, in notifications
    return jsonify([{
NameError: name 'jsonify' is not defined
