2022-02-09 11:19:36,982 ERROR: Exception on /notifications [GET] [in /home/sema/venv/lib/python3.9/site-packages/flask/app.py:1454]
Traceback (most recent call last):
  File "/home/sema/venv/lib/python3.9/site-packages/flask/app.py", line 2070, in wsgi_app
    response = self.full_dispatch_request()
  File "/home/sema/venv/lib/python3.9/site-packages/flask/app.py", line 1515, in full_dispatch_request
    rv = self.handle_user_exception(e)
  File "/home/sema/venv/lib/python3.9/site-packages/flask/app.py", line 1513, in full_dispatch_request
    rv = self.dispatch_request()
  File "/home/sema/venv/lib/python3.9/site-packages/flask/app.py", line 1499, in dispatch_request
    return self.ensure_sync(self.view_functions[rule.endpoint])(**req.view_args)
  File "/home/sema/venv/lib/python3.9/site-packages/flask_login/utils.py", line 272, in decorated_view
    return func(*args, **kwargs)
  File "/home/sema/microblog/app/main/routes.py", line 202, in notifications
    return jsonify([{
NameError: name 'jsonify' is not defined
2022-02-09 11:19:41,568 ERROR: Exception on /notifications [GET] [in /home/sema/venv/lib/python3.9/site-packages/flask/app.py:1454]
Traceback (most recent call last):
  File "/home/sema/venv/lib/python3.9/site-packages/flask/app.py", line 2070, in wsgi_app
    response = self.full_dispatch_request()
  File "/home/sema/venv/lib/python3.9/site-packages/flask/app.py", line 1515, in full_dispatch_request
    rv = self.handle_user_exception(e)
  File "/home/sema/venv/lib/python3.9/site-packages/flask/app.py", line 1513, in full_dispatch_request
    rv = self.dispatch_request()
  File "/home/sema/venv/lib/python3.9/site-packages/flask/app.py", line 1499, in dispatch_request
    return self.ensure_sync(self.view_functions[rule.endpoint])(**req.view_args)
  File "/home/sema/venv/lib/python3.9/site-packages/flask_login/utils.py", line 272, in decorated_view
    return func(*args, **kwargs)
  File "/home/sema/microblog/app/main/routes.py", line 202, in notifications
    return jsonify([{
NameError: name 'jsonify' is not defined
2022-02-09 11:19:46,991 ERROR: Exception on /notifications [GET] [in /home/sema/venv/lib/python3.9/site-packages/flask/app.py:1454]
Traceback (most recent call last):
  File "/home/sema/venv/lib/python3.9/site-packages/flask/app.py", line 2070, in wsgi_app
    response = self.full_dispatch_request()
  File "/home/sema/venv/lib/python3.9/site-packages/flask/app.py", line 1515, in full_dispatch_request
    rv = self.handle_user_exception(e)
  File "/home/sema/venv/lib/python3.9/site-packages/flask/app.py", line 1513, in full_dispatch_request
    rv = self.dispatch_request()
  File "/home/sema/venv/lib/python3.9/site-packages/flask/app.py", line 1499, in dispatch_request
    return self.ensure_sync(self.view_functions[rule.endpoint])(**req.view_args)
  File "/home/sema/venv/lib/python3.9/site-packages/flask_login/utils.py", line 272, in decorated_view
    return func(*args, **kwargs)
  File "/home/sema/microblog/app/main/routes.py", line 202, in notifications
    return jsonify([{
NameError: name 'jsonify' is not defined
2022-02-09 11:19:51,578 ERROR: Exception on /notifications [GET] [in /home/sema/venv/lib/python3.9/site-packages/flask/app.py:1454]
Traceback (most recent call last):
  File "/home/sema/venv/lib/python3.9/site-packages/flask/app.py", line 2070, in wsgi_app
    response = self.full_dispatch_request()
  File "/home/sema/venv/lib/python3.9/site-packages/flask/app.py", line 1515, in full_dispatch_request
    rv = self.handle_user_exception(e)
  File "/home/sema/venv/lib/python3.9/site-packages/flask/app.py", line 1513, in full_dispatch_request
    rv = self.dispatch_request()
  File "/home/sema/venv/lib/python3.9/site-packages/flask/app.py", line 1499, in dispatch_request
    return self.ensure_sync(self.view_functions[rule.endpoint])(**req.view_args)
  File "/home/sema/venv/lib/python3.9/site-packages/flask_login/utils.py", line 272, in decorated_view
    return func(*args, **kwargs)
  File "/home/sema/microblog/app/main/routes.py", line 202, in notifications
    return jsonify([{
NameError: name 'jsonify' is not defined
2022-02-09 11:19:56,996 ERROR: Exception on /notifications [GET] [in /home/sema/venv/lib/python3.9/site-packages/flask/app.py:1454]
Traceback (most recent call last):
  File "/home/sema/venv/lib/python3.9/site-packages/flask/app.py", line 2070, in wsgi_app
    response = self.full_dispatch_request()
  File "/home/sema/venv/lib/python3.9/site-packages/flask/app.py", line 1515, in full_dispatch_request
    rv = self.handle_user_exception(e)
  File "/home/sema/venv/lib/python3.9/site-packages/flask/app.py", line 1513, in full_dispatch_request
    rv = self.dispatch_request()
  File "/home/sema/venv/lib/python3.9/site-packages/flask/app.py", line 1499, in dispatch_request
    return self.ensure_sync(self.view_functions[rule.endpoint])(**req.view_args)
  File "/home/sema/venv/lib/python3.9/site-packages/flask_login/utils.py", line 272, in decorated_view
    return func(*args, **kwargs)
  File "/home/sema/microblog/app/main/routes.py", line 202, in notifications
    return jsonify([{
NameError: name 'jsonify' is not defined
2022-02-09 11:20:01,578 ERROR: Exception on /notifications [GET] [in /home/sema/venv/lib/python3.9/site-packages/flask/app.py:1454]
Traceback (most recent call last):
  File "/home/sema/venv/lib/python3.9/site-packages/flask/app.py", line 2070, in wsgi_app
    response = self.full_dispatch_request()
  File "/home/sema/venv/lib/python3.9/site-packages/flask/app.py", line 1515, in full_dispatch_request
    rv = self.handle_user_exception(e)
  File "/home/sema/venv/lib/python3.9/site-packages/flask/app.py", line 1513, in full_dispatch_request
    rv = self.dispatch_request()
  File "/home/sema/venv/lib/python3.9/site-packages/flask/app.py", line 1499, in dispatch_request
    return self.ensure_sync(self.view_functions[rule.endpoint])(**req.view_args)
  File "/home/sema/venv/lib/python3.9/site-packages/flask_login/utils.py", line 272, in decorated_view
    return func(*args, **kwargs)
  File "/home/sema/microblog/app/main/routes.py", line 202, in notifications
    return jsonify([{
NameError: name 'jsonify' is not defined
2022-02-09 11:20:07,036 ERROR: Exception on /notifications [GET] [in /home/sema/venv/lib/python3.9/site-packages/flask/app.py:1454]
Traceback (most recent call last):
  File "/home/sema/venv/lib/python3.9/site-packages/flask/app.py", line 2070, in wsgi_app
    response = self.full_dispatch_request()
  File "/home/sema/venv/lib/python3.9/site-packages/flask/app.py", line 1515, in full_dispatch_request
    rv = self.handle_user_exception(e)
  File "/home/sema/venv/lib/python3.9/site-packages/flask/app.py", line 1513, in full_dispatch_request
    rv = self.dispatch_request()
  File "/home/sema/venv/lib/python3.9/site-packages/flask/app.py", line 1499, in dispatch_request
    return self.ensure_sync(self.view_functions[rule.endpoint])(**req.view_args)
  File "/home/sema/venv/lib/python3.9/site-packages/flask_login/utils.py", line 272, in decorated_view
    return func(*args, **kwargs)
  File "/home/sema/microblog/app/main/routes.py", line 202, in notifications
    return jsonify([{
NameError: name 'jsonify' is not defined
2022-02-09 11:20:11,587 ERROR: Exception on /notifications [GET] [in /home/sema/venv/lib/python3.9/site-packages/flask/app.py:1454]
Traceback (most recent call last):
  File "/home/sema/venv/lib/python3.9/site-packages/flask/app.py", line 2070, in wsgi_app
    response = self.full_dispatch_request()
  File "/home/sema/venv/lib/python3.9/site-packages/flask/app.py", line 1515, in full_dispatch_request
    rv = self.handle_user_exception(e)
  File "/home/sema/venv/lib/python3.9/site-packages/flask/app.py", line 1513, in full_dispatch_request
    rv = self.dispatch_request()
  File "/home/sema/venv/lib/python3.9/site-packages/flask/app.py", line 1499, in dispatch_request
    return self.ensure_sync(self.view_functions[rule.endpoint])(**req.view_args)
  File "/home/sema/venv/lib/python3.9/site-packages/flask_login/utils.py", line 272, in decorated_view
    return func(*args, **kwargs)
  File "/home/sema/microblog/app/main/routes.py", line 202, in notifications
    return jsonify([{
NameError: name 'jsonify' is not defined
2022-02-09 11:20:18,036 ERROR: Exception on /notifications [GET] [in /home/sema/venv/lib/python3.9/site-packages/flask/app.py:1454]
Traceback (most recent call last):
  File "/home/sema/venv/lib/python3.9/site-packages/flask/app.py", line 2070, in wsgi_app
    response = self.full_dispatch_request()
  File "/home/sema/venv/lib/python3.9/site-packages/flask/app.py", line 1515, in full_dispatch_request
    rv = self.handle_user_exception(e)
  File "/home/sema/venv/lib/python3.9/site-packages/flask/app.py", line 1513, in full_dispatch_request
    rv = self.dispatch_request()
  File "/home/sema/venv/lib/python3.9/site-packages/flask/app.py", line 1499, in dispatch_request
    return self.ensure_sync(self.view_functions[rule.endpoint])(**req.view_args)
  File "/home/sema/venv/lib/python3.9/site-packages/flask_login/utils.py", line 272, in decorated_view
    return func(*args, **kwargs)
  File "/home/sema/microblog/app/main/routes.py", line 202, in notifications
    return jsonify([{
NameError: name 'jsonify' is not defined
