2022-02-09 11:13:28,889 ERROR: Exception on /notifications [GET] [in /home/sema/venv/lib/python3.9/site-packages/flask/app.py:1454]
Traceback (most recent call last):
  File "/home/sema/venv/lib/python3.9/site-packages/flask/app.py", line 2070, in wsgi_app
    response = self.full_dispatch_request()
  File "/home/sema/venv/lib/python3.9/site-packages/flask/app.py", line 1515, in full_dispatch_request
    rv = self.handle_user_exception(e)
  File "/home/sema/venv/lib/python3.9/site-packages/flask/app.py", line 1513, in full_dispatch_request
    rv = self.dispatch_request()
  File "/home/sema/venv/lib/python3.9/site-packages/flask/app.py", line 1499, in dispatch_request
    return self.ensure_sync(self.view_functions[rule.endpoint])(**req.view_args)
  File "/home/sema/venv/lib/python3.9/site-packages/flask_login/utils.py", line 272, in decorated_view
    return func(*args, **kwargs)
  File "/home/sema/microblog/app/main/routes.py", line 200, in notifications
    notifications = current_user.notifications.filter(
AttributeError: 'User' object has no attribute 'notifications'
2022-02-09 11:13:37,597 ERROR: Exception on /notifications [GET] [in /home/sema/venv/lib/python3.9/site-packages/flask/app.py:1454]
Traceback (most recent call last):
  File "/home/sema/venv/lib/python3.9/site-packages/flask/app.py", line 2070, in wsgi_app
    response = self.full_dispatch_request()
  File "/home/sema/venv/lib/python3.9/site-packages/flask/app.py", line 1515, in full_dispatch_request
    rv = self.handle_user_exception(e)
  File "/home/sema/venv/lib/python3.9/site-packages/flask/app.py", line 1513, in full_dispatch_request
    rv = self.dispatch_request()
  File "/home/sema/venv/lib/python3.9/site-packages/flask/app.py", line 1499, in dispatch_request
    return self.ensure_sync(self.view_functions[rule.endpoint])(**req.view_args)
  File "/home/sema/venv/lib/python3.9/site-packages/flask_login/utils.py", line 272, in decorated_view
    return func(*args, **kwargs)
  File "/home/sema/microblog/app/main/routes.py", line 200, in notifications
    notifications = current_user.notifications.filter(
AttributeError: 'User' object has no attribute 'notifications'
2022-02-09 11:13:38,897 ERROR: Exception on /notifications [GET] [in /home/sema/venv/lib/python3.9/site-packages/flask/app.py:1454]
Traceback (most recent call last):
  File "/home/sema/venv/lib/python3.9/site-packages/flask/app.py", line 2070, in wsgi_app
    response = self.full_dispatch_request()
  File "/home/sema/venv/lib/python3.9/site-packages/flask/app.py", line 1515, in full_dispatch_request
    rv = self.handle_user_exception(e)
  File "/home/sema/venv/lib/python3.9/site-packages/flask/app.py", line 1513, in full_dispatch_request
    rv = self.dispatch_request()
  File "/home/sema/venv/lib/python3.9/site-packages/flask/app.py", line 1499, in dispatch_request
    return self.ensure_sync(self.view_functions[rule.endpoint])(**req.view_args)
  File "/home/sema/venv/lib/python3.9/site-packages/flask_login/utils.py", line 272, in decorated_view
    return func(*args, **kwargs)
  File "/home/sema/microblog/app/main/routes.py", line 200, in notifications
    notifications = current_user.notifications.filter(
AttributeError: 'User' object has no attribute 'notifications'
2022-02-09 11:13:48,601 ERROR: Exception on /notifications [GET] [in /home/sema/venv/lib/python3.9/site-packages/flask/app.py:1454]
Traceback (most recent call last):
  File "/home/sema/venv/lib/python3.9/site-packages/flask/app.py", line 2070, in wsgi_app
    response = self.full_dispatch_request()
  File "/home/sema/venv/lib/python3.9/site-packages/flask/app.py", line 1515, in full_dispatch_request
    rv = self.handle_user_exception(e)
  File "/home/sema/venv/lib/python3.9/site-packages/flask/app.py", line 1513, in full_dispatch_request
    rv = self.dispatch_request()
  File "/home/sema/venv/lib/python3.9/site-packages/flask/app.py", line 1499, in dispatch_request
    return self.ensure_sync(self.view_functions[rule.endpoint])(**req.view_args)
  File "/home/sema/venv/lib/python3.9/site-packages/flask_login/utils.py", line 272, in decorated_view
    return func(*args, **kwargs)
  File "/home/sema/microblog/app/main/routes.py", line 200, in notifications
    notifications = current_user.notifications.filter(
AttributeError: 'User' object has no attribute 'notifications'
2022-02-09 11:13:48,908 ERROR: Exception on /notifications [GET] [in /home/sema/venv/lib/python3.9/site-packages/flask/app.py:1454]
Traceback (most recent call last):
  File "/home/sema/venv/lib/python3.9/site-packages/flask/app.py", line 2070, in wsgi_app
    response = self.full_dispatch_request()
  File "/home/sema/venv/lib/python3.9/site-packages/flask/app.py", line 1515, in full_dispatch_request
    rv = self.handle_user_exception(e)
  File "/home/sema/venv/lib/python3.9/site-packages/flask/app.py", line 1513, in full_dispatch_request
    rv = self.dispatch_request()
  File "/home/sema/venv/lib/python3.9/site-packages/flask/app.py", line 1499, in dispatch_request
    return self.ensure_sync(self.view_functions[rule.endpoint])(**req.view_args)
  File "/home/sema/venv/lib/python3.9/site-packages/flask_login/utils.py", line 272, in decorated_view
    return func(*args, **kwargs)
  File "/home/sema/microblog/app/main/routes.py", line 200, in notifications
    notifications = current_user.notifications.filter(
AttributeError: 'User' object has no attribute 'notifications'
2022-02-09 11:13:58,339 INFO: Microblog startup [in /home/sema/microblog/app/__init__.py:77]
2022-02-09 11:13:58,981 ERROR: Exception on /notifications [GET] [in /home/sema/venv/lib/python3.9/site-packages/flask/app.py:1454]
Traceback (most recent call last):
  File "/home/sema/venv/lib/python3.9/site-packages/flask/app.py", line 2070, in wsgi_app
    response = self.full_dispatch_request()
  File "/home/sema/venv/lib/python3.9/site-packages/flask/app.py", line 1515, in full_dispatch_request
    rv = self.handle_user_exception(e)
  File "/home/sema/venv/lib/python3.9/site-packages/flask/app.py", line 1513, in full_dispatch_request
    rv = self.dispatch_request()
  File "/home/sema/venv/lib/python3.9/site-packages/flask/app.py", line 1499, in dispatch_request
    return self.ensure_sync(self.view_functions[rule.endpoint])(**req.view_args)
  File "/home/sema/venv/lib/python3.9/site-packages/flask_login/utils.py", line 272, in decorated_view
    return func(*args, **kwargs)
  File "/home/sema/microblog/app/main/routes.py", line 202, in notifications
    return jsonify([{
NameError: name 'jsonify' is not defined
2022-02-09 11:13:59,589 ERROR: Exception on /notifications [GET] [in /home/sema/venv/lib/python3.9/site-packages/flask/app.py:1454]
Traceback (most recent call last):
  File "/home/sema/venv/lib/python3.9/site-packages/flask/app.py", line 2070, in wsgi_app
    response = self.full_dispatch_request()
  File "/home/sema/venv/lib/python3.9/site-packages/flask/app.py", line 1515, in full_dispatch_request
    rv = self.handle_user_exception(e)
  File "/home/sema/venv/lib/python3.9/site-packages/flask/app.py", line 1513, in full_dispatch_request
    rv = self.dispatch_request()
  File "/home/sema/venv/lib/python3.9/site-packages/flask/app.py", line 1499, in dispatch_request
    return self.ensure_sync(self.view_functions[rule.endpoint])(**req.view_args)
  File "/home/sema/venv/lib/python3.9/site-packages/flask_login/utils.py", line 272, in decorated_view
    return func(*args, **kwargs)
  File "/home/sema/microblog/app/main/routes.py", line 202, in notifications
    return jsonify([{
NameError: name 'jsonify' is not defined
2022-02-09 11:14:08,922 ERROR: Exception on /notifications [GET] [in /home/sema/venv/lib/python3.9/site-packages/flask/app.py:1454]
Traceback (most recent call last):
  File "/home/sema/venv/lib/python3.9/site-packages/flask/app.py", line 2070, in wsgi_app
    response = self.full_dispatch_request()
  File "/home/sema/venv/lib/python3.9/site-packages/flask/app.py", line 1515, in full_dispatch_request
    rv = self.handle_user_exception(e)
  File "/home/sema/venv/lib/python3.9/site-packages/flask/app.py", line 1513, in full_dispatch_request
    rv = self.dispatch_request()
  File "/home/sema/venv/lib/python3.9/site-packages/flask/app.py", line 1499, in dispatch_request
    return self.ensure_sync(self.view_functions[rule.endpoint])(**req.view_args)
  File "/home/sema/venv/lib/python3.9/site-packages/flask_login/utils.py", line 272, in decorated_view
    return func(*args, **kwargs)
  File "/home/sema/microblog/app/main/routes.py", line 202, in notifications
    return jsonify([{
NameError: name 'jsonify' is not defined
2022-02-09 11:14:10,601 ERROR: Exception on /notifications [GET] [in /home/sema/venv/lib/python3.9/site-packages/flask/app.py:1454]
Traceback (most recent call last):
  File "/home/sema/venv/lib/python3.9/site-packages/flask/app.py", line 2070, in wsgi_app
    response = self.full_dispatch_request()
  File "/home/sema/venv/lib/python3.9/site-packages/flask/app.py", line 1515, in full_dispatch_request
    rv = self.handle_user_exception(e)
  File "/home/sema/venv/lib/python3.9/site-packages/flask/app.py", line 1513, in full_dispatch_request
    rv = self.dispatch_request()
  File "/home/sema/venv/lib/python3.9/site-packages/flask/app.py", line 1499, in dispatch_request
    return self.ensure_sync(self.view_functions[rule.endpoint])(**req.view_args)
  File "/home/sema/venv/lib/python3.9/site-packages/flask_login/utils.py", line 272, in decorated_view
    return func(*args, **kwargs)
  File "/home/sema/microblog/app/main/routes.py", line 202, in notifications
    return jsonify([{
NameError: name 'jsonify' is not defined
